Workbook

Sheet BEO
I1: ORDER NUMBER | J1: 060725-12
A2: CLIENT | B2: Kol Ami | I2: EVENT DATE | J2: 44353
A3: CONTACT | B3: Lisa & Jordan Tafflin | I3: GUESTS | J3: 81 - ADULTS
A4: PHONE | B4: Alyssa 856-524-6938 (Coordinator) | I4: EVENT START | J4: 7pm
A5: ADDRESS | B5: 1101 Springdale Road | I5: EVENT END | J5: 11:30pm
A6: CITY, ST | B6: Cherry Hill, NJ | I6: FW STAFF | J6: FULL STAFF
I7: STAFF ARRIVAL | J7: 3pm//////4pm?
A8: NO DAIRY, NO NUTS, GLUTEN ALLERGIES
A9: PASSED APPS - METAL
A11: 120 | B11: Quilted Franks
A12: qt | B12: Dusseldorf Mustard
A14: 100 | B14: Sesame Crusted Chicken
A15: # | B15: no nuts PJ come up with adip
A17: 70 | B17: Veggie Spring Rolls
A18: # | B18: Thai Chili Dip
A20: 60 | B20: Mini Beef Wellington
A21: # | B21: Horsey Sauce - MUST BE DAIRY FREE!!!!
A23: 80 | B23: Potato Latkes
A24: Qt | B24: Spiced Apple Drizzle
A26: 2 qts | B26: Tuna & Avocado Ceviche - SERVED ON A PORCELAIN SPOON
A27: 100 | B27: atop an English Cucumber petak
A28: # | B28: Topped w/ Wonton Threads
A30: 80 | B30: Korean Fried Chicken
A31: 1 | B31: qt bbq PJ
A33: 80 | B33: Polpetti - NO CHEESE
B35: *****MAKE SURE TO TAKE GARNISH FOR THE PASSING PLATTERS******
A36: DELI
A38: 100 | B38: Mini Challah - in bread baskets on each table
A39: see Nick | B39: Herb Infused Dairy-Free Butter
A41: 1 | B41: Challah with Silver Platter
B42: Gio please order
A43: PRESENTED APPETIZERS
B45: Terrific Tafflin Display - GLUTEN FREE
A46: 55 | B46: Petite Chicken Kabobs
A47: 55 | B47: Petite Beef Kabobs
A48: 2 platters 10# | B48: Veggie Crudite & Sliced Fruit
B49: Dried Fruit, Olives
A50: 2 qts | B50: Hummus
A51: 2 qts | B51: Bruschetta
A53: 3+ | B53: Artisanal Crackers & Crostini
...

Sheet Servers
I1: ORDER NUMBER | J1: =BEO!J1 -> 060725-12
A2: CLIENT | B2: =BEO!B2 -> Kol Ami | I2: EVENT DATE | J2: =BEO!J2 -> 44353
A3: CONTACT | B3: =BEO!B3 -> Lisa & Jordan Tafflin | I3: GUESTS | J3: =BEO!J3 -> 81 - ADULTS
A4: PHONE | B4: =BEO!B4 -> Alyssa 856-524-6938 (Coordinator) | I4: EVENT START | J4: =BEO!J4 -> 7pm
A5: ADDRESS | B5: =BEO!B5 -> 1101 Springdale Road | I5: EVENT END | J5: =BEO!J5 -> 11:30pm
A6: CITY, ST | B6: =BEO!B6 -> Cherry Hill, NJ | I6: FW STAFF | J6: =BEO!J6 -> FULL STAFF
I7: STAFF ARRIVAL | J7: =BEO!J7 -> 3pm//////4pm?
A8: BEVERAGES
A10: 7+6+4+3 | B10: COKE - DIET COKE - SPRITE - GINGER ALE
A11: 4+4+3+2 | B11: SIMPLE SYRUP - SOUR MIX - GRENANDINE - LIME JUICE
A12: 6+3+3 | B12: CRANBERRY - PINEAPPLE - ORANGE JUICE
A13: 6+3+2 | B13: SELTZER - BITTERS - LEMON JUICE
A14: 2+2+6 | B14: OLIVES - CHERRIES - ORANGES
A15: cs each +12+12 | B15: TONIC - CLUB SODA - LEMONS - LIMES
B16: Sig Drink: Miami Vice (strawberry Dacquri/PinaColda) NEED BLENDER and PLASTIC STRAWS
A17: tammi | B17: REGULAR COFFEE - DECAF COFFEE - HOT WATER
B18: COFFEE SET UP - SWEETENERS, CREAMER, TEA BAGS, TEASPOONS, SIGNAGE
A20: PAPER PRODUCTS/CHINA - CUTLERY - GLASSWARE
A22: RENTED | B22: GLASSWARE, CHINA & CUTLERY SERVICE
A23: YES | B23: COCKTAIL NAPKINS - PASSED APPS, APP STATION, DESSERT STATION, BAR
A24: YES | B24: PLASTIC SODA CUPS - FOR BACK UP
A25: RENTED | B25: LINEN NAPKINS
A26: RENTED | B26: LINEN TABLE COVERS
A28: NOTES
B30: ***TABLESIDE COFFEE SERVICE***
B32: ON OTHER BEO
A39: TIMELINE
B50: ALYSSA WILL SEND

Sheet Packout
I1: ORDER NUMBER | J1: =BEO!J1 -> 060725-12
A2: CLIENT | B2: =BEO!B2 -> Kol Ami | I2: EVENT DATE | J2: =BEO!J2 -> 44353
A3: CONTACT | B3: =BEO!B3 -> Lisa & Jordan Tafflin | I3: GUESTS | J3: =BEO!J3 -> 81 - ADULTS
A4: PHONE | B4: =BEO!B4 -> Alyssa 856-524-6938 (Coordinator) | I4: EVENT START | J4: =BEO!J4 -> 7pm
A5: ADDRESS | B5: =BEO!B5 -> 1101 Springdale Road | I5: EVENT END | J5: =BEO!J5 -> 11:30pm
A6: CITY, ST | B6: =BEO!B6 -> Cherry Hill, NJ | I6: FW STAFF | J6: =BEO!J6 -> FULL STAFF
I7: STAFF ARRIVAL | J7: =BEO!J7 -> 3pm//////4pm?
A8: EQUIPMENT
B9: PARTY BOX
B10: BUFFET/ROOM ITEMS
B11: LONG CHAFER WITH WATER PAN
B12: FULL HOTEL PAN
B13: 1/2 HOTEL PAN - SHALLOW OR DEEP
B14: GRILL/GRATE CHAFER
B15: SIZZLE PLATTER
B16: ROUND CHAFER WITH WATER PAN
B17: ROUND HOTEL PAN
B18: CARVING STATION SET UP - HEAT LAMP - WOOD BOARD - CARVING KNIFE & FORK - EXTENSION CORD
B19: PASTA STATION SET UP - BURNERS & BUTANE - SMALL FRYING PANS - RUBBER SPATULAS
B20: CAKE KNIFE & SERVER
... B66: ADDITIONAL DÉCOR - HOUSE OVERLAYS
